Workbook

Sheet Summary
A1: Orbyte GreenReady — Executive Summary
A3: Role: GreenReady is a new module inside Orbyte (Alpha Red Pro Sdn Bhd). All figures are from Orbyte's point of view: new income the module earns minus the extra cost to build and run it.
A4: All figures are projections from the Assumptions sheet (team estimates plus cited public data). They are estimates, not guarantees.
A6: Customers using GreenReady (Y5) | C6: 5-Year Customer Benefits (RM) | E6: CO2e Avoided, credited (5-yr, t)
A7: =Volumes!B9 -> 10000 | C7: =ROI!B10 -> 1609378.8 | E7: =Benefits!G9 -> 1179.7101
A9: Orbyte ROI on GreenReady (5-yr) | C9: Customer ROI (5-yr) | E9: NPV @ discount rate (RM)
A10: =ROI!B19 -> 0.66984856 | C10: =ROI!B20 -> 2.0471426 | E10: =ROI!D36 -> 344999.89
A12: Orbyte break-even (cumulative) | C12: Year-5 operating margin | E12: Customer break-even
A13: =ROI!B22 -> Y2 | C13: =ROI!B21 -> 0.49169169 | E13: =ROI!B24 -> Y1
A15: Key Takeaways
A16: ="• The recurring burden: "&TEXT(Volumes!E10,"#,##0")&" bill analyses over 5 years, saving about "&TEXT(Benefits!B9,"#,##0")&" admin hours for customers." -> • The recurring burden: 149,760 bill analyses over 5 years, saving about 58,032 admin hours for customers.
A17: ="• A typical solar upgrade saves about RM"&TEXT(Upgrade_Calc!C7,"#,##0")&" a year with a "&TEXT(Upgrade_Calc!F7,"0.0")&"-year payback; LED pays back in "&TEXT(Upgrade_Calc!F5,"0.0")&" years." -> • A typical solar upgrade saves about RM20,069 a year with a 3.0-year payback; LED pays back in 1.2 years.
A18: ="• Customers earn a "&TEXT(ROI!B20,"0%")&" return on what they pay (analyses and Preparation Packs), even after crediting GreenReady with only "&TEXT(Assumptions!$B$41,"0%")&" of energy savings." -> • Customers earn a 205% return on what they pay (analyses and Preparation Packs), even after crediting GreenReady with only 25% of energy savings.
A19: ="• Customers gain more than they pay from "&ROI!B24&" ("&TEXT(ROI!I5,"0%")&" ROI in Y1); GreenReady is profitable from "&ROI!B23&" and fully recovers its Y1 spend by "&ROI!B22&"." -> • Customers gain more than they pay from Y1 (161% ROI in Y1); GreenReady is profitable from Y2 and fully recovers its Y1 spend by Y2.
A20: ="• SMEs pay "&TEXT(IF(ROI!C10>0,(Pricing_Income!B9+Pricing_Income!C9)/ROI!C10,0),"0%")&" of 5-year income through the Orbyte credit wallet; suppliers and investors pay "&TEXT(IF(ROI!C10>0,(Pricing_Income!D9+Pricing_Income!E9)/ROI!C10,0),"0%")&"." -> • SMEs pay 20% of 5-year income through the Orbyte credit wallet; suppliers and investors pay 80%.
A21: ="• By Year 5 GreenReady reaches "&TEXT(Volumes!D9,"0.0%")&" of the serviceable market, so the projection does not rely on mass adoption." -> • By Year 5 GreenReady reaches 5.1% of the serviceable market, so the projection does not rely on mass adoption.
A22: ="• Key risk: without supplier and investor fees, the pack would need to cost about RM"&TEXT(ROI!B27,"#,##0")&" to break even, so early partner sign-ups matter most." -> • Key risk: without supplier and investor fees, the pack would need to cost about RM337 to break even, so early partner sign-ups matter most.
A24: Core Assumptions (full price list on the Pricing_Model sheet)
A25: ="Free credit RM"&TEXT(Assumptions!$B$92,"0")&" · RM"&TEXT(Assumptions!$B$91,"0.00")&" per analysis · Pack RM"&TEXT(Assumptions!$B$95,"0")&" · Supplier fee RM"&TEXT(Assumptions!$B$101,"0")&"/connection · Investor subscription RM"&TEXT(Assumptions!$B$102,"#,##0")&"/month · Tariff RM"&TEXT(Assumptions!$B$39,"0.0000")&"/kWh · Grid factor "&TEXT(Assumptions!$B$40,"0.000")&" kg/kWh · Discount rate "&TEXT(Assumptions!$B$107,"0%") -> Free credit RM10 · RM2.00 per analysis · Pack RM79 · Supplier fee RM200/connection · Investor subscription RM2,500/month · Tariff RM0.5068/kWh · Grid factor 0.740 kg/kWh · Discount rate 30%
A26: Money for upgrades moves off-platform through licensed lenders and suppliers; GreenReady earns fees only, never interest or loan commission.

Sheet Pricing_Model
A1: How GreenReady Charges — Role, Price List and Money Flow
A3: 1. Our role
A4: Party | B4: Role | E4: What they get
A5: Orbyte (Alpha Red Pro Sdn Bhd) | B5: Owner and operator of the GreenReady module (the vendor in this model) | E5: New usage-based income from SMEs, banks and suppliers; SMEs open Orbyte every month
A6: SME owner and staff | B6: Customer — uses GreenReady inside Orbyte, pays per use from the Orbyte credit wallet | E6: Bill checked in minutes, fair upgrade comparison, bank-ready Preparation Pack
A7: Banks and green investors | B7: Partner — monthly subscription to see anonymised, checked listings | E7: Pre-checked green-loan applicants matched to their own criteria
A8: SEDA-registered and equipment suppliers | B8: Partner — pays per accepted connection | E8: Qualified leads backed by real bill data, only after the owner says yes
A9: GreenReady earns fees only. Loans, deposits and upgrade payments never pass through Orbyte: banks and suppliers deal with the SME directly. No credit scores, ratings or financial advice.
A11: 2. Price list (every price links to the Assumptions sheet)
A12: Item | B12: Price | C12: Who pays | D12: When it is charged | E12: What is included | F12: How it is paid
A13: Free starting credit | B13: =Assumptions!$B$92 -> 10 | C13: Orbyte gives it (cost = lost income) | D13: When the company first opens GreenReady | E13: Covers the first analyses (RM10 ÷ RM2 = 5 bills). One per company, checked by SSM number | F13: Orbyte credit wallet
A14: Bill analysis | B14: =Assumptions!$B$91 -> 2 | C14: SME | D14: Each TNB bill analysed after the free credit | E14: Charge-line reading, 8 tariff checks, spike alert, 6-month trend, upgrade comparison | F14: Orbyte credit wallet
A15: Preparation Pack + 90-day partner access | B15: =Assumptions!$B$95 -> 79 | C15: SME | D15: When the owner decides to act on an upgrade | E15: 6-month checked bill summary and upgrade estimates (PDF), anonymous listing, 90 days of investor and supplier connections | F15: Orbyte credit wallet
A16: Supplier connection | B16: =Assumptions!$B$101 -> 200 | C16: Supplier | D16: Only after the owner accepts the supplier's request | E16: Company name, contact person, site address and exact usage for sizing | F16: Monthly invoice
A17: Bank / investor subscription | B17: =Assumptions!$B$102 -> 2500 | C17: Bank or green investor | D17: Every month | E17: Unlimited browsing of anonymised listings, criteria match, repayment check on its own terms, Expression of Interest after acceptance | F17: Monthly invoice
A18: Not charged: browsing GreenReady, viewing the first results, the owner accepting or declining requests, and partners viewing listings they already pay for. No monthly fee for SMEs and no per-seat fees, in line with Orbyte's usage-based pricing [44].
A20: 3. What GreenReady reuses from Orbyte (no extra cost in this model)
A21: Orbyte feature | B21: Used in GreenReady for
A22: Connect — sign-in, roles, approval workflows | B22: Owner, staff and partner roles; the owner approves each listing and each connection
A23: Credit wallet (one wallet for every module) | B23: Free starting credit, bill analyses and Preparation Packs
A24: eClaim | B24: When staff claim a TNB bill, GreenReady analyses it automatically (the trigger)
A25: eSign and audit log | B25: Owner signs a supplier's firm quotation; every upload, approval and request is recorded
A27: 4. Worked example — one SME in its first year
A28: Step | B28: What happens | E28: Paid by | F28: Orbyte earns (RM)
A29: 1. Joins | B29: Kilang A opens GreenReady in Orbyte and receives the free credit | E29: Orbyte | F29: =0 -> 0
A30: 2. Monthly checks | B30: 12 bills analysed: the first 5 use the free credit, 7 are paid | E30: SME | F30: =MAX(0,12-Assumptions!$B$93)*Assumptions!$B$91 -> 14
A31: 3. Plans an upgrade | B31: Solar looks worth it, so the owner buys a Preparation Pack | E31: SME | F31: =Assumptions!$B$95 -> 79
A32: 4. Suppliers connect | B32: Two suppliers send proposals; the owner accepts both | E32: Suppliers | F32: =2*Assumptions!$B$101 -> 400
A33: 5. Bank connects | B33: A subscribed bank sends an Expression of Interest; covered by its subscription | E33: Bank | F33: =0 -> 0
A34: 6. Deal off-platform | B34: Loan and installation are agreed directly between Kilang A, the bank and the supplier | E34: — | F34: =0 -> 0
A35: Total from Kilang A | B35: Kilang A pays the analyses and the pack; suppliers pay the connections | F35: =SUM(F29:F34) -> 493
A36: Kilang A pays in total | B36: Analyses + Preparation Pack | F36: =F30+F31 -> 93
A38: 5. Five-year income by stream (from Pricing_Income)
A39: Stream | B39: 5-yr income (RM) | C39: Share
A40: Bill analyses (SME) | B40: =Pricing_Income!B9 -> 199520 | C40: =IF(Pricing_Income!F9>0,Pricing_Income!B9/Pricing_Income!F9,0) -> 0.074526737
A41: Preparation Packs (SME) | B41: =Pricing_Income!C9 -> 328640 | C41: =IF(Pricing_Income!F9>0,Pricing_Income!C9/Pricing_Income!F9,0) -> 0.12275695
A42: Supplier connections | B42: =Pricing_Income!D9 -> 649000 | C42: =IF(Pricing_Income!F9>0,Pricing_Income!D9/Pricing_Income!F9,0) -> 0.24242107
A43: Bank / investor subscriptions | B43: =Pricing_Income!E9 -> 1500000 | C43: =IF(Pricing_Income!F9>0,Pricing_Income!E9/Pricing_Income!F9,0) -> 0.56029524
A44: Total | B44: =Pricing_Income!F9 -> 2677160 | C44: =SUM(C40:C43) -> 1

Sheet Assumptions
A1: Orbyte GreenReady — Financial Model Assumptions
A2: Yellow cells with blue text are editable inputs. Every other sheet pulls from here — change a value and the whole model updates.
A3: Colour key: blue = input · black = formula · green = link from another sheet. Basis column: Source = taken from a cited publication · Derived = calculated from cited figures · Benchmark = set against a cited comparison · Target = to be replaced with our user-test result · Design choice = a scenario setting we chose.
A6: A. Market size | I6: Basis [Ref]
A7: Micro enterprises in Malaysia (2023) | B7: 767421 | G7: firms | H7: Latest establishment count (2023 profile). MSMEs were 39.7% of GDP in 2025 [40]. | I7: Source [1][40]
A8: Small enterprises in Malaysia (2023) | B8: 314465 | G8: firms | H8: Total addressable market (TAM) context. | I8: Source [1]
A9: MSMEs in manufacturing (2023) | B9: 59316 | G9: firms | H9: Energy-heavy: 84% of manufacturers rank energy management a key priority [16]. | I9: Source [1]
A10: Food & beverage service establishments | B10: 136453 | G10: firms | H10: Energy-heavy: cooking, refrigeration and aircon run all day. | I10: Source [2]
A11: Serviceable addressable market (SAM) | B11: =Assumptions!$B$9+Assumptions!$B$10 -> 195769 | G11: firms | H11: Formula: manufacturing MSMEs + F&B establishments (the two most electricity-intensive customer groups). | I11: Derived [1][2]
A13: B. Adoption funnel (by year) | I13: Basis [Ref]
A14: Item | B14: Y1 | C14: Y2 | D14: Y3 | E14: Y4 | F14: Y5 | G14: Unit | H14: Source / note | I14: Basis [Ref]
A15: Active Customers using GreenReady (base case) | B15: 300 | C15: 1500 | D15: 3000 | E15: 6000 | F15: 10000 | G15: Customers | H15: Y1 pilot of 300 is half of the 600+ SMEs one bank (RHB) engaged in a single quarter [18]. Y5 = about 5% of SAM, reached through Orbyte's existing customer users. | I15: Benchmark [18]
A16: Volume scenario multiplier | B16: 1 | G16: × | H16: Scenario lever: 80% = low case, 120% = high case. | I16: Scenario lever
A17: TNB bills per customer per year | B17: 12 | G17: bills | H17: TNB bills every month — this is the recurring burden. | I17: Source [37]
A18: Monthly active rate (bills analysed) | B18: 0.6 | G18: % | H18: Share of monthly bills analysed. Bills arrive automatically when staff submit the TNB bill through Orbyte eClaim, or the owner forwards it. Design target; confirm in the pilot. | I18: Target — pilot
A19: Preparation Pack rate (% of active customers per year) | B19: 0.2 | G19: % | H19: Paid conversion is 8–12% in the top quartile of freemium products and ~25% when the purchase follows a clear usage trigger [42]. Here the trigger is a bill showing an upgrade worth doing; 48% of SMEs are seeking efficiency technology [16]. 20% sits below the trigger-based benchmark. Most sensitive assumption — test in the pilot. | I19: Benchmark [16][42]
A20: Listing rate (% of packs put on the Opportunity Board) | B20: 0.52 | G20: % | H20: 48% of SMEs self-fund green initiatives [17], so the other 52% look for outside funding or partners. | I20: Derived [17]
A21: Upgrade completion rate (% of listings per year) | B21: 0.26 | G21: % | H21: 52% of non-adopters plan to act within two years [17] ⇒ about 26% a year. | I21: Derived [17]
A22: Accepted supplier connections per listing | B22: 1.5 | G22: connections | H22: Lead marketplaces share each lead with 3–5 installers [19]; 1.5 accepted is conservative. | I22: Benchmark [19]
A23: Paying investor / bank subscribers | B23: 2 | C23: 6 | D23: 10 | E23: 14 | F23: 18 | G23: partners | H23: Malaysia has 27 commercial and 16 Islamic banks [23], plus DFIs that deliver green customer facilities such as LCTF [24]. Y5 = 18 is under half of the banks alone. | I23: Benchmark [23][24]
A25: C. Customer time value | I25: Basis [Ref]
A26: Clerical support worker median wage | B26: 2693 | G26: RM/month | H26: Conservative value of time spent on bills (owner time is worth more). | I26: Source [14]
A27: Maximum working hours per week | B27: 45 | G27: hours | H27: Employment Act limit. | I27: Source [15]
A28: Working hours per month | B28: =Assumptions!$B$27*52/12 -> 195 | G28: hours | H28: Formula: weekly hours × 52 ÷ 12. | I28: Derived [15]
A29: Value of one hour of admin time | B29: =Assumptions!$B$26/Assumptions!$B$28 -> 13.810256 | G29: RM/hour | H29: Formula: monthly wage ÷ monthly hours. | I29: Derived [14][15]
A30: Manual bill check time | B30: 20 | G30: minutes | H30: SME owners spend about 11 hours a week on admin and finance tasks (2026 survey) [35]. Replace with the timed spreadsheet test from the demo. | I30: Target — user test
A31: GreenReady bill check time | B31: 3 | G31: minutes | H31: Forward bill, read summary. Replace with the timed demo result. | I31: Target — user test
A32: Manual upgrade evaluation per pack | B32: 4 | G32: hours | H32: Compare quotes and work out savings and payback in a spreadsheet. Replace with the timed test. | I32: Target — user test
A33: GreenReady upgrade evaluation per pack | B33: 0.25 | G33: hours | H33: Review and approve the generated pack. | I33: Target — user test
A35: D. Energy and carbon | I35: Basis [Ref]
A36: TNB energy charge (Low Voltage General) | B36: 0.2703 | G36: RM/kWh | H36: Tariff schedule from 1 Jul 2025. | I36: Source [3]
A37: TNB capacity charge | B37: 0.0883 | G37: RM/kWh | H37: Tariff schedule from 1 Jul 2025. | I37: Source [3]
A38: TNB network charge | B38: 0.1482 | G38: RM/kWh | H38: Tariff schedule from 1 Jul 2025. | I38: Source [3]
A39: Variable tariff used for savings | B39: =Assumptions!$B$36+Assumptions!$B$37+Assumptions!$B$38 -> 0.5068 | G39: RM/kWh | H39: Formula: energy + capacity + network. Base rates fixed to 31 Dec 2027 [39]. Excludes AFA (+3.61 sen/kWh in Oct 2026) [39], retail charge and tax, so savings are understated. | I39: Derived [3][39]
A40: Grid emission factor, Peninsular Malaysia 2024 | B40: 0.74 | G40: kg CO2e/kWh | H40: Provisional, subject to government endorsement. | I40: Source [4]
A41: Share of upgrade savings credited to GreenReady | B41: 0.25 | G41: % | H41: 48% of SMEs already look for efficiency technology on their own [16], so GreenReady is one driver among several. Only a quarter of savings is claimed. | I41: Design choice [16]
A42: First-year installation factor | B42: 0.5 | G42: % | H42: Mid-year convention: upgrades finish evenly through the year, so they save half a year in the year installed. | I42: Method [33]
A44: E. Green equipment upgrades — what an 'upgrade' means | I44: Basis [Ref]
A45: An 'upgrade' is energy-saving equipment a customer buys after using GreenReady: LED lighting, inverter air-conditioners or rooftop solar. GreenReady does not sell the equipment. It checks which option pays off and connects the customer to suppliers and funders. Upgrades feed the model in two places only: the customer's electricity savings (Benefits) and CO2e avoided. GreenReady's own income comes from fees, not from the equipment.
A46: Operating days per year (all upgrades) | B46: 312 | G46: days | H46: 6-day week × 52 weeks (Employment Act gives one rest day a week). | I46: Derived [15]
...

Sheet Upgrade_Calc
A1: Green Equipment Upgrade Calculator — what one typical customer upgrade saves
A2: An upgrade = energy-saving equipment the customer buys after using GreenReady (LED lighting, inverter aircon or rooftop solar). GreenReady does not sell it; it shows which one pays off and connects the customer to suppliers and funders. Inputs: Assumptions section E.
A4: Upgrade type | B4: Annual kWh saved | C4: Annual savings (RM) | D4: CO2e avoided (t/yr) | E4: Installed cost (RM) | F4: Simple payback (years) | G4: Mix share | H4: How kWh is calculated
A5: LED lighting | B5: =Assumptions!$B$47*(Assumptions!$B$48-Assumptions!$B$49)/1000*Assumptions!$B$50*Assumptions!$B$46 -> 2695.68 | C5: =B5*Assumptions!$B$39 -> 1366.1706 | D5: =B5*Assumptions!$B$40/1000 -> 1.9948032 | E5: =Assumptions!$B$47*Assumptions!$B$53 -> 1644.4 | F5: =IF(C5>0,E5/C5,0) -> 1.2036564 | G5: =Assumptions!$B$65 -> 0.5 | H5: tubes × (old W − new W) ÷ 1000 × hours/day × days/year
A6: Inverter aircon | B6: =Assumptions!$B$54*Assumptions!$B$55*Assumptions!$B$56*Assumptions!$B$46*Assumptions!$B$57 -> 3150.576 | C6: =B6*Assumptions!$B$39 -> 1596.7119 | D6: =B6*Assumptions!$B$40/1000 -> 2.3314262 | E6: =Assumptions!$B$54*Assumptions!$B$60 -> 6600 | F6: =IF(C6>0,E6/C6,0) -> 4.1334945 | G6: =Assumptions!$B$66 -> 0.35 | H6: units × kW × hours/day × days/year × saving %
A7: Rooftop solar | B7: =Assumptions!$B$61*Assumptions!$B$62*Assumptions!$B$63 -> 39600 | C7: =B7*Assumptions!$B$39 -> 20069.28 | D7: =B7*Assumptions!$B$40/1000 -> 29.304 | E7: =Assumptions!$B$61*Assumptions!$B$64 -> 60000 | F7: =IF(C7>0,E7/C7,0) -> 2.9896439 | G7: =Assumptions!$B$67 -> 0.15 | H7: kWp × specific yield × self-consumption %
A8: Weighted average upgrade | B8: =SUMPRODUCT(B5:B7,$G$5:$G$7) -> 8390.5416 | C8: =SUMPRODUCT(C5:C7,$G$5:$G$7) -> 4252.3265 | D8: =SUMPRODUCT(D5:D7,$G$5:$G$7) -> 6.2090008 | E8: =SUMPRODUCT(E5:E7,$G$5:$G$7) -> 12132.2 | F8: =IF(C8>0,E8/C8,0) -> 2.8530735 | G8: =SUM(G5:G7) -> 1 | H8: Mix-weighted; payback = weighted cost ÷ weighted savings
A11: Why it matters: the weighted average (row 8) is used on the Benefits sheet to value the electricity savings and CO2e of upgrades the customers complete. Savings = kWh × variable tariff. CO2e = kWh × grid emission factor ÷ 1000. Payback = installed cost ÷ annual savings (no financing cost, no tariff increase).
A12: The solar row reproduces the proposal's worked example: 30 kWp × 1,320 kWh/kWp = 39,600 kWh ≈ RM20,069 and 29.3 t CO2e per year.

Sheet Volumes
A1: Volumes — Adoption Funnel by Year
A2: Active Customers → bills analysed → paid analyses → Preparation Packs → board listings → completed upgrades → supplier connections.
A4: Year | B4: Active Customers | C4: New Customers | D4: % of SAM | E4: Bills analysed | F4: Free analyses used | G4: Paid analyses | H4: Packs generated | I4: Board listings | J4: Upgrades completed | K4: Cumulative upgrades | L4: Upgrades saving this year* | M4: Supplier connections
A5: Y1 | B5: =ROUND(Assumptions!B15*Assumptions!$B$16,0) -> 300 | C5: =MAX(0,B5-0) -> 300 | D5: =IF(Assumptions!$B$11>0,B5/Assumptions!$B$11,0) -> 0.0015324183 | E5: =ROUND(B5*Assumptions!$B$17*Assumptions!$B$18,0) -> 2160 | F5: =MIN(E5,C5*Assumptions!$B$93) -> 1500 | G5: =E5-F5 -> 660 | H5: =ROUND(B5*Assumptions!$B$19,0) -> 60 | I5: =ROUND(H5*Assumptions!$B$20,0) -> 31 | J5: =ROUND(I5*Assumptions!$B$21,0) -> 8 | K5: =J5 -> 8 | L5: =0+J5*Assumptions!$B$42 -> 4 | M5: =ROUND(I5*Assumptions!$B$22,0) -> 47
A6: Y2 | B6: =ROUND(Assumptions!C15*Assumptions!$B$16,0) -> 1500 | C6: =MAX(0,B6-B5) -> 1200 | D6: =IF(Assumptions!$B$11>0,B6/Assumptions!$B$11,0) -> 0.0076620915 | E6: =ROUND(B6*Assumptions!$B$17*Assumptions!$B$18,0) -> 10800 | F6: =MIN(E6,C6*Assumptions!$B$93) -> 6000 | G6: =E6-F6 -> 4800 | H6: =ROUND(B6*Assumptions!$B$19,0) -> 300 | I6: =ROUND(H6*Assumptions!$B$20,0) -> 156 | J6: =ROUND(I6*Assumptions!$B$21,0) -> 41 | K6: =K5+J6 -> 49 | L6: =K5+J6*Assumptions!$B$42 -> 28.5 | M6: =ROUND(I6*Assumptions!$B$22,0) -> 234
A7: Y3 | B7: =ROUND(Assumptions!D15*Assumptions!$B$16,0) -> 3000 | C7: =MAX(0,B7-B6) -> 1500 | D7: =IF(Assumptions!$B$11>0,B7/Assumptions!$B$11,0) -> 0.015324183 | E7: =ROUND(B7*Assumptions!$B$17*Assumptions!$B$18,0) -> 21600 | F7: =MIN(E7,C7*Assumptions!$B$93) -> 7500 | G7: =E7-F7 -> 14100 | H7: =ROUND(B7*Assumptions!$B$19,0) -> 600 | I7: =ROUND(H7*Assumptions!$B$20,0) -> 312 | J7: =ROUND(I7*Assumptions!$B$21,0) -> 81 | K7: =K6+J7 -> 130 | L7: =K6+J7*Assumptions!$B$42 -> 89.5 | M7: =ROUND(I7*Assumptions!$B$22,0) -> 468
A8: Y4 | B8: =ROUND(Assumptions!E15*Assumptions!$B$16,0) -> 6000 | C8: =MAX(0,B8-B7) -> 3000 | D8: =IF(Assumptions!$B$11>0,B8/Assumptions!$B$11,0) -> 0.030648366 | E8: =ROUND(B8*Assumptions!$B$17*Assumptions!$B$18,0) -> 43200 | F8: =MIN(E8,C8*Assumptions!$B$93) -> 15000 | G8: =E8-F8 -> 28200 | H8: =ROUND(B8*Assumptions!$B$19,0) -> 1200 | I8: =ROUND(H8*Assumptions!$B$20,0) -> 624 | J8: =ROUND(I8*Assumptions!$B$21,0) -> 162 | K8: =K7+J8 -> 292 | L8: =K7+J8*Assumptions!$B$42 -> 211 | M8: =ROUND(I8*Assumptions!$B$22,0) -> 936
A9: Y5 | B9: =ROUND(Assumptions!F15*Assumptions!$B$16,0) -> 10000 | C9: =MAX(0,B9-B8) -> 4000 | D9: =IF(Assumptions!$B$11>0,B9/Assumptions!$B$11,0) -> 0.05108061 | E9: =ROUND(B9*Assumptions!$B$17*Assumptions!$B$18,0) -> 72000 | F9: =MIN(E9,C9*Assumptions!$B$93) -> 20000 | G9: =E9-F9 -> 52000 | H9: =ROUND(B9*Assumptions!$B$19,0) -> 2000 | I9: =ROUND(H9*Assumptions!$B$20,0) -> 1040 | J9: =ROUND(I9*Assumptions!$B$21,0) -> 270 | K9: =K8+J9 -> 562 | L9: =K8+J9*Assumptions!$B$42 -> 427 | M9: =ROUND(I9*Assumptions!$B$22,0) -> 1560
A10: 5-Year Total | B10: =SUM(B5:B9) -> 20800 | C10: =SUM(C5:C9) -> 10000 | E10: =SUM(E5:E9) -> 149760 | F10: =SUM(F5:F9) -> 50000 | G10: =SUM(G5:G9) -> 99760 | H10: =SUM(H5:H9) -> 4160 | I10: =SUM(I5:I9) -> 2163 | J10: =SUM(J5:J9) -> 562 | M10: =SUM(M5:M9) -> 3245
A12: * Upgrades saving this year = all upgrades finished in earlier years (full year) + this year's upgrades × first-year installation factor (half year).
A13: Bills analysed = active customers × 12 × monthly active rate. Each new company's free credit covers its first analyses; the rest are paid from the Orbyte credit wallet.
A14: Active Customers (B) sums customer-years across the 5 years; the number of customers using GreenReady in Year 5 is the Y5 row.

Sheet Benefits
A1: 1) Benefits — Value Created for Customers
A3: Year | B3: Admin hours saved | C3: Bill-check time saved (RM) | D3: Upgrade-evaluation time saved (RM) | E3: Energy savings credited to GreenReady (RM) | F3: Total Customer Benefits (RM) | G3: CO2e avoided credited (t)
A4: Y1 | B4: =Volumes!E5*(Assumptions!$B$30-Assumptions!$B$31)/60+Volumes!H5*(Assumptions!$B$32-Assumptions!$B$33) -> 837 | C4: =Volumes!E5*(Assumptions!$B$30-Assumptions!$B$31)/60*Assumptions!$B$29 -> 8451.8769 | D4: =Volumes!H5*(Assumptions!$B$32-Assumptions!$B$33)*Assumptions!$B$29 -> 3107.3077 | E4: =Volumes!L5*Upgrade_Calc!$C$8*Assumptions!$B$41 -> 4252.3265 | F4: =C4+D4+E4 -> 15811.511 | G4: =Volumes!L5*Upgrade_Calc!$D$8*Assumptions!$B$41 -> 6.2090008
A5: Y2 | B5: =Volumes!E6*(Assumptions!$B$30-Assumptions!$B$31)/60+Volumes!H6*(Assumptions!$B$32-Assumptions!$B$33) -> 4185 | C5: =Volumes!E6*(Assumptions!$B$30-Assumptions!$B$31)/60*Assumptions!$B$29 -> 42259.385 | D5: =Volumes!H6*(Assumptions!$B$32-Assumptions!$B$33)*Assumptions!$B$29 -> 15536.538 | E5: =Volumes!L6*Upgrade_Calc!$C$8*Assumptions!$B$41 -> 30297.826 | F5: =C5+D5+E5 -> 88093.749 | G5: =Volumes!L6*Upgrade_Calc!$D$8*Assumptions!$B$41 -> 44.239131
A6: Y3 | B6: =Volumes!E7*(Assumptions!$B$30-Assumptions!$B$31)/60+Volumes!H7*(Assumptions!$B$32-Assumptions!$B$33) -> 8370 | C6: =Volumes!E7*(Assumptions!$B$30-Assumptions!$B$31)/60*Assumptions!$B$29 -> 84518.769 | D6: =Volumes!H7*(Assumptions!$B$32-Assumptions!$B$33)*Assumptions!$B$29 -> 31073.077 | E6: =Volumes!L7*Upgrade_Calc!$C$8*Assumptions!$B$41 -> 95145.805 | F6: =C6+D6+E6 -> 210737.65 | G6: =Volumes!L7*Upgrade_Calc!$D$8*Assumptions!$B$41 -> 138.92639
A7: Y4 | B7: =Volumes!E8*(Assumptions!$B$30-Assumptions!$B$31)/60+Volumes!H8*(Assumptions!$B$32-Assumptions!$B$33) -> 16740 | C7: =Volumes!E8*(Assumptions!$B$30-Assumptions!$B$31)/60*Assumptions!$B$29 -> 169037.54 | D7: =Volumes!H8*(Assumptions!$B$32-Assumptions!$B$33)*Assumptions!$B$29 -> 62146.154 | E7: =Volumes!L8*Upgrade_Calc!$C$8*Assumptions!$B$41 -> 224310.22 | F7: =C7+D7+E7 -> 455493.91 | G7: =Volumes!L8*Upgrade_Calc!$D$8*Assumptions!$B$41 -> 327.52479
A8: Y5 | B8: =Volumes!E9*(Assumptions!$B$30-Assumptions!$B$31)/60+Volumes!H9*(Assumptions!$B$32-Assumptions!$B$33) -> 27900 | C8: =Volumes!E9*(Assumptions!$B$30-Assumptions!$B$31)/60*Assumptions!$B$29 -> 281729.23 | D8: =Volumes!H9*(Assumptions!$B$32-Assumptions!$B$33)*Assumptions!$B$29 -> 103576.92 | E8: =Volumes!L9*Upgrade_Calc!$C$8*Assumptions!$B$41 -> 453935.85 | F8: =C8+D8+E8 -> 839242.01 | G8: =Volumes!L9*Upgrade_Calc!$D$8*Assumptions!$B$41 -> 662.81083
A9: 5-Year Total | B9: =SUM(B4:B8) -> 58032 | C9: =SUM(C4:C8) -> 585996.8 | D9: =SUM(D4:D8) -> 215440 | E9: =SUM(E4:E8) -> 807942.03 | F9: =SUM(F4:F8) -> 1609378.8 | G9: =SUM(G4:G8) -> 1179.7101
A11: Bill-check time saved = bills checked × (manual − GreenReady minutes) ÷ 60 × hourly value of admin time
A12: Upgrade-evaluation time saved = packs × (manual − GreenReady hours) × hourly value of admin time
A13: Energy savings credited = upgrades saving this year × weighted RM saved per upgrade × share credited to GreenReady (25%)
A14: CO2e avoided credited = upgrades saving this year × weighted t CO2e per upgrade × share credited to GreenReady
A15: Benefits are value to customers, not cash to GreenReady. The full energy savings of facilitated upgrades are 4× the credited figure.

Sheet Pricing_Income
A1: 2) Pricing / Income — New Income Orbyte Earns from the GreenReady Module
A3: Year | B3: Bill analyses — credit wallet (RM) | C3: Preparation Packs — credit wallet (RM) | D3: Supplier connection fees (RM) | E3: Investor / bank subscriptions (RM) | F3: Total Income (RM)
A4: Y1 | B4: =Volumes!G5*Assumptions!$B$91 -> 1320 | C4: =Volumes!H5*Assumptions!$B$95 -> 4740 | D4: =Volumes!M5*Assumptions!$B$101 -> 9400 | E4: =Assumptions!B23*Assumptions!$B$102*12 -> 60000 | F4: =SUM(B4:E4) -> 75460
A5: Y2 | B5: =Volumes!G6*Assumptions!$B$91 -> 9600 | C5: =Volumes!H6*Assumptions!$B$95 -> 23700 | D5: =Volumes!M6*Assumptions!$B$101 -> 46800 | E5: =Assumptions!C23*Assumptions!$B$102*12 -> 180000 | F5: =SUM(B5:E5) -> 260100
A6: Y3 | B6: =Volumes!G7*Assumptions!$B$91 -> 28200 | C6: =Volumes!H7*Assumptions!$B$95 -> 47400 | D6: =Volumes!M7*Assumptions!$B$101 -> 93600 | E6: =Assumptions!D23*Assumptions!$B$102*12 -> 300000 | F6: =SUM(B6:E6) -> 469200
A7: Y4 | B7: =Volumes!G8*Assumptions!$B$91 -> 56400 | C7: =Volumes!H8*Assumptions!$B$95 -> 94800 | D7: =Volumes!M8*Assumptions!$B$101 -> 187200 | E7: =Assumptions!E23*Assumptions!$B$102*12 -> 420000 | F7: =SUM(B7:E7) -> 758400
A8: Y5 | B8: =Volumes!G9*Assumptions!$B$91 -> 104000 | C8: =Volumes!H9*Assumptions!$B$95 -> 158000 | D8: =Volumes!M9*Assumptions!$B$101 -> 312000 | E8: =Assumptions!F23*Assumptions!$B$102*12 -> 540000 | F8: =SUM(B8:E8) -> 1114000
A9: 5-Year Total | B9: =SUM(B4:B8) -> 199520 | C9: =SUM(C4:C8) -> 328640 | D9: =SUM(D4:D8) -> 649000 | E9: =SUM(E4:E8) -> 1500000 | F9: =SUM(F4:F8) -> 2677160
A11: Bill analyses = paid analyses × price per analysis, deducted from the Orbyte credit wallet after the free starting credit is used
A12: Preparation Packs = packs × pack price (includes 90 days of investor and supplier connections), deducted from the credit wallet
A13: Supplier fees = accepted supplier connections × fee per connection (supplier pays only after the owner accepts)
A14: Subscriptions = paying investors / banks × monthly fee × 12
A15: Usage-based, like Orbyte's other modules: SMEs pay only when they use it. No interest, loan commission or upgrade money passes through Orbyte.

Sheet Spendings
A1: 3) Spendings — GreenReady's Own Cost to Build and Run the Module
A3: Year | B3: AI document reading (RM) | C3: WhatsApp messaging (RM) | D3: Cloud hosting (RM) | E3: Team salaries + statutory (RM) | F3: Customer acquisition (RM) | G3: Compliance + legal (RM) | H3: Partnerships (RM) | I3: MVP hardening (RM) | J3: Payment processing (RM) | K3: Total Spend (RM)
A4: Y1 | B4: =(Volumes!E5+Volumes!H5*Assumptions!$B$73)*Assumptions!$B$72*Assumptions!$B$71/3600*Assumptions!$B$70 -> 34.750585 | C4: =Volumes!B5*Assumptions!$B$74*Assumptions!$B$75*Assumptions!$B$70 -> 36.7515 | D4: =Assumptions!$B$78+Volumes!B5*Assumptions!$B$79 -> 4814.172 | E4: =Assumptions!B80*Assumptions!$B$81*12*(1+Assumptions!$B$82+Assumptions!$B$83+Assumptions!$B$84) -> 83739.576 | F4: =Volumes!C5*Assumptions!$B$85 -> 6000 | G4: =Assumptions!B86 -> 15000 | H4: =Assumptions!$B$88 -> 10000 | I4: =Assumptions!$B$87 -> 20000 | J4: =(Pricing_Income!B4+Pricing_Income!C4)*Assumptions!$B$96+IF(Assumptions!$B$94>0,(Pricing_Income!B4+Pricing_Income!C4)/Assumptions!$B$94,0)*Assumptions!$B$97 -> 484.8 | K4: =SUM(B4:J4) -> 140110.05
A5: Y2 | B5: =(Volumes!E6+Volumes!H6*Assumptions!$B$73)*Assumptions!$B$72*Assumptions!$B$71/3600*Assumptions!$B$70 -> 173.75292 | C5: =Volumes!B6*Assumptions!$B$74*Assumptions!$B$75*Assumptions!$B$70 -> 183.7575 | D5: =Assumptions!$B$78+Volumes!B6*Assumptions!$B$79 -> 7214.172 | E5: =Assumptions!C80*Assumptions!$B$81*12*(1+Assumptions!$B$82+Assumptions!$B$83+Assumptions!$B$84) -> 125609.36 | F5: =Volumes!C6*Assumptions!$B$85 -> 24000 | G5: =Assumptions!C86 -> 8000 | H5: =Assumptions!$B$88 -> 10000 | I5: =0 -> 0 | J5: =(Pricing_Income!B5+Pricing_Income!C5)*Assumptions!$B$96+IF(Assumptions!$B$94>0,(Pricing_Income!B5+Pricing_Income!C5)/Assumptions!$B$94,0)*Assumptions!$B$97 -> 2664 | K5: =SUM(B5:J5) -> 177845.05
A6: Y3 | B6: =(Volumes!E7+Volumes!H7*Assumptions!$B$73)*Assumptions!$B$72*Assumptions!$B$71/3600*Assumptions!$B$70 -> 347.50585 | C6: =Volumes!B7*Assumptions!$B$74*Assumptions!$B$75*Assumptions!$B$70 -> 367.515 | D6: =Assumptions!$B$78+Volumes!B7*Assumptions!$B$79 -> 10214.172 | E6: =Assumptions!D80*Assumptions!$B$81*12*(1+Assumptions!$B$82+Assumptions!$B$83+Assumptions!$B$84) -> 209348.94 | F6: =Volumes!C7*Assumptions!$B$85 -> 30000 | G6: =Assumptions!D86 -> 8000 | H6: =Assumptions!$B$88 -> 10000 | I6: =0 -> 0 | J6: =(Pricing_Income!B6+Pricing_Income!C6)*Assumptions!$B$96+IF(Assumptions!$B$94>0,(Pricing_Income!B6+Pricing_Income!C6)/Assumptions!$B$94,0)*Assumptions!$B$97 -> 6048 | K6: =SUM(B6:J6) -> 274326.13
A7: Y4 | B7: =(Volumes!E8+Volumes!H8*Assumptions!$B$73)*Assumptions!$B$72*Assumptions!$B$71/3600*Assumptions!$B$70 -> 695.0117 | C7: =Volumes!B8*Assumptions!$B$74*Assumptions!$B$75*Assumptions!$B$70 -> 735.03 | D7: =Assumptions!$B$78+Volumes!B8*Assumptions!$B$79 -> 16214.172 | E7: =Assumptions!E80*Assumptions!$B$81*12*(1+Assumptions!$B$82+Assumptions!$B$83+Assumptions!$B$84) -> 334958.3 | F7: =Volumes!C8*Assumptions!$B$85 -> 60000 | G7: =Assumptions!E86 -> 10000 | H7: =Assumptions!$B$88 -> 10000 | I7: =0 -> 0 | J7: =(Pricing_Income!B7+Pricing_Income!C7)*Assumptions!$B$96+IF(Assumptions!$B$94>0,(Pricing_Income!B7+Pricing_Income!C7)/Assumptions!$B$94,0)*Assumptions!$B$97 -> 12096 | K7: =SUM(B7:J7) -> 444698.52
A8: Y5 | B8: =(Volumes!E9+Volumes!H9*Assumptions!$B$73)*Assumptions!$B$72*Assumptions!$B$71/3600*Assumptions!$B$70 -> 1158.3528 | C8: =Volumes!B9*Assumptions!$B$74*Assumptions!$B$75*Assumptions!$B$70 -> 1225.05 | D8: =Assumptions!$B$78+Volumes!B9*Assumptions!$B$79 -> 24214.172 | E8: =Assumptions!F80*Assumptions!$B$81*12*(1+Assumptions!$B$82+Assumptions!$B$83+Assumptions!$B$84) -> 418697.88 | F8: =Volumes!C9*Assumptions!$B$85 -> 80000 | G8: =Assumptions!F86 -> 10000 | H8: =Assumptions!$B$88 -> 10000 | I8: =0 -> 0 | J8: =(Pricing_Income!B8+Pricing_Income!C8)*Assumptions!$B$96+IF(Assumptions!$B$94>0,(Pricing_Income!B8+Pricing_Income!C8)/Assumptions!$B$94,0)*Assumptions!$B$97 -> 20960 | K8: =SUM(B8:J8) -> 566255.45
A9: 5-Year Total | B9: =SUM(B4:B8) -> 2409.3739 | C9: =SUM(C4:C8) -> 2548.104 | D9: =SUM(D4:D8) -> 62670.86 | E9: =SUM(E4:E8) -> 1172354.1 | F9: =SUM(F4:F8) -> 200000 | G9: =SUM(G4:G8) -> 51000 | H9: =SUM(H4:H8) -> 50000 | I9: =SUM(I4:I8) -> 20000 | ... K9: =SUM(K4:K8) -> 1603235.2
A11: AI reading = (bills analysed + packs × quotes per pack) × GPU seconds per document × GPU USD/hour ÷ 3600 × RM per USD
A12: Messaging = active customers × billable messages × USD per message × RM per USD
A13: Hosting = base + active customers × per-customer cost · Salaries = FTE × median professional wage × 12 × (1 + EPF + SOCSO + EIS)
A14: Customer acquisition = new customers that year × cost per new customer · MVP hardening is a one-time Year 1 cost
A15: Payment processing = SME credit spent in GreenReady × gateway % + number of credit top-ups × fixed fee
A16: AI and messaging costs are tiny per customer; people are the main cost, so margins grow as volume grows.

Sheet ROI
A2: ROI — Year-by-Year and 5-Year Summary
A4: Year | B4: Total Customer Benefits (RM) | C4: Total Income (RM) | D4: Total Spend (RM) | E4: GreenReady Net = Income − Spend (RM) | F4: Cumulative Net (RM) | G4: Fees paid by Customers (RM) | H4: Customer Net = Benefits − Fees (RM) | I4: Customer ROI (%)
A5: Y1 | B5: =Benefits!F4 -> 15811.511 | C5: =Pricing_Income!F4 -> 75460 | D5: =Spendings!K4 -> 140110.05 | E5: =C5-D5 -> -64650.05 | F5: =E5 -> -64650.05 | G5: =Pricing_Income!B4+Pricing_Income!C4 -> 6060 | H5: =B5-G5 -> 9751.5111 | I5: =IF(G5>0,(B5-G5)/G5,0) -> 1.6091602
A6: Y2 | B6: =Benefits!F5 -> 88093.749 | C6: =Pricing_Income!F5 -> 260100 | D6: =Spendings!K5 -> 177845.05 | E6: =C6-D6 -> 82254.954 | F6: =F5+E6 -> 17604.903 | G6: =Pricing_Income!B5+Pricing_Income!C5 -> 33300 | H6: =B6-G6 -> 54793.749 | I6: =IF(G6>0,(B6-G6)/G6,0) -> 1.6454579
A7: Y3 | B7: =Benefits!F6 -> 210737.65 | C7: =Pricing_Income!F6 -> 469200 | D7: =Spendings!K6 -> 274326.13 | E7: =C7-D7 -> 194873.87 | F7: =F6+E7 -> 212478.77 | G7: =Pricing_Income!B6+Pricing_Income!C6 -> 75600 | H7: =B7-G7 -> 135137.65 | I7: =IF(G7>0,(B7-G7)/G7,0) -> 1.7875351
A8: Y4 | B8: =Benefits!F7 -> 455493.91 | C8: =Pricing_Income!F7 -> 758400 | D8: =Spendings!K7 -> 444698.52 | E8: =C8-D8 -> 313701.48 | F8: =F7+E8 -> 526180.25 | G8: =Pricing_Income!B7+Pricing_Income!C7 -> 151200 | H8: =B8-G8 -> 304293.91 | I8: =IF(G8>0,(B8-G8)/G8,0) -> 2.0125259
A9: Y5 | B9: =Benefits!F8 -> 839242.01 | C9: =Pricing_Income!F8 -> 1114000 | D9: =Spendings!K8 -> 566255.45 | E9: =C9-D9 -> 547744.55 | F9: =F8+E9 -> 1073924.8 | G9: =Pricing_Income!B8+Pricing_Income!C8 -> 262000 | H9: =B9-G9 -> 577242.01 | I9: =IF(G9>0,(B9-G9)/G9,0) -> 2.2032138
A10: 5-Year Total | B10: =SUM(B5:B9) -> 1609378.8 | C10: =SUM(C5:C9) -> 2677160 | D10: =SUM(D5:D9) -> 1603235.2 | E10: =SUM(E5:E9) -> 1073924.8 | G10: =SUM(G5:G9) -> 528160 | H10: =SUM(H5:H9) -> 1081218.8 | I10: =IF(G10>0,(B10-G10)/G10,0) -> 2.0471426
A13: 5-Year ROI Summary
A14: Total Customer benefits (5-yr, RM) | B14: =B10 -> 1609378.8 | C14: Value created for customers
A15: Total income (5-yr, RM) | B15: =C10 -> 2677160 | C15: Paid by customers, suppliers and investors
A16: Total spend (5-yr, RM) | B16: =D10 -> 1603235.2 | C16: GreenReady's own costs
A17: GreenReady net profit / (loss) (5-yr, RM) | B17: =C10-D10 -> 1073924.8
A19: GreenReady ROI = (Income − Spend) / Spend | B19: =IF(D10>0,(C10-D10)/D10,0) -> 0.66984856 | C19: Return on GreenReady's own spending over 5 years
A20: Customer ROI = (Benefits − Customer fees) / Customer fees | B20: =IF(G10>0,(B10-G10)/G10,0) -> 2.0471426 | C20: Return customers earn on what they pay (analyses + Preparation Packs, 5-yr)
A21: Year-5 operating margin = Y5 net / Y5 income | B21: =IF(C9>0,E9/C9,0) -> 0.49169169 | C21: Shows the business once it has scaled
A22: First year with positive cumulative net (vendor) | B22: =IFERROR(INDEX(A5:A9,MATCH(TRUE(),INDEX(F5:F9>=0,0),0)),"Beyond Y5") -> Y2 | C22: Cumulative break-even year
A23: First year with positive annual net (vendor) | B23: =IFERROR(INDEX(A5:A9,MATCH(TRUE(),INDEX(E5:E9>0,0),0)),"Beyond Y5") -> Y2 | C23: Operating break-even year
A24: First year customers gain more than they pay | B24: =IFERROR(INDEX(A5:A9,MATCH(TRUE(),INDEX(H5:H9>0,0),0)),"Beyond Y5") -> Y1 | C24: Customer break-even year
A25: Break-Even Check
A26: Break-even pack price needed (RM) | B26: =IF(Volumes!H10>0,MAX(0,(D10-Pricing_Income!B9-Pricing_Income!D9-Pricing_Income!E9)/Volumes!H10),0) -> 0 | C26: Pack price at which 5-yr income equals 5-yr spend, holding the other fees fixed
A27: Pack price needed if supplier and investor fees were zero (RM) | B27: =IF(Volumes!H10>0,MAX(0,(D10-Pricing_Income!B9)/Volumes!H10),0) -> 337.43154 | C27: Stress test: income from SMEs alone must cover all spend
A28: Current pack price (RM) | B28: =Assumptions!$B$95 -> 79
A29: Net Present Value (NPV) — GreenReady Cash Flows
A30: Year | B30: Net cash flow (RM) | C30: Discount factor | D30: Present value (RM)
A31: Y1 | B31: =E5 -> -64650.05 | C31: =1/(1+Assumptions!$B$107)^1 -> 0.76923077 | D31: =B31*C31 -> -49730.808
A32: Y2 | B32: =E6 -> 82254.954 | C32: =1/(1+Assumptions!$B$107)^2 -> 0.59171598 | D32: =B32*C32 -> 48671.57
A33: Y3 | B33: =E7 -> 194873.87 | C33: =1/(1+Assumptions!$B$107)^3 -> 0.45516614 | D33: =B33*C33 -> 88699.985
A34: Y4 | B34: =E8 -> 313701.48 | C34: =1/(1+Assumptions!$B$107)^4 -> 0.3501278 | D34: =B34*C34 -> 109835.61
A35: Y5 | B35: =E9 -> 547744.55 | C35: =1/(1+Assumptions!$B$107)^5 -> 0.26932907 | D35: =B35*C35 -> 147523.53
A36: Net Present Value (NPV) | D36: =SUM(D31:D35) -> 344999.89
A38: NPV discounts each year's net cash flow to today's value at the discount rate on Assumptions. Year-end cash flows assumed.

Sheet Dashboard
A1: Orbyte GreenReady — 5-Year Financial Projection
A2: Source: ROI sheet rows 5–9 (formula-linked; charts update when assumptions change).

Sheet Business_Model
A1: Business Model — who pays, for what, and why it works
A2: Canvas text is descriptive; every number links to the model, so it updates when Assumptions change.
A4: Canvas block | B4: GreenReady | C4: Key figure | D4: Link
A5: Customer segments | B5: Micro and small SMEs in manufacturing and F&B (energy-heavy); green investors and banks; SEDA-registered and equipment suppliers; Orbyte as platform partner | C5: =Assumptions!$B$11 -> 195769 | D5: SAM (firms)
A6: Value proposition — Customer | B6: Bill check in minutes, paid per use from the Orbyte credit wallet; a bank-ready Preparation Pack with 90 days of investor and supplier connections when the owner is ready to upgrade | C6: =ROI!B20 -> 2.0471426 | D6: Customer ROI (%, 5-yr)
A7: Value proposition — Investor | B7: Pre-checked, anonymised green deal-flow matched to the investor's own criteria | C7: =Assumptions!$B$102*12 -> 30000 | D7: Subscription (RM/yr)
A8: Value proposition — Supplier | B8: Qualified leads backed by real bill data; pay only when the owner accepts | C8: =Assumptions!$B$101 -> 200 | D8: Fee per connection (RM)
A9: Value proposition — Orbyte | B9: A new usage-based module that brings a monthly reason to open Orbyte, more credit-wallet spend and new partner income from banks and suppliers | C9: =Pricing_Income!F9 -> 2677160 | D9: 5-yr new income (RM)
A10: Channels | B10: Inside Orbyte (in-app launch to existing customers), WhatsApp bill forwarding, partner web portal, bank SME units, supplier associations | C10: =Assumptions!$B$85 -> 20 | D10: CAC per new customer (RM)
A11: Customer relationships | B11: Self-serve inside Orbyte: free starting credit, then pay per use; owner approves every listing and connection through Orbyte's approval workflow | C11: =Assumptions!$B$19 -> 0.2 | D11: Pack rate (%)
A12: Revenue streams | B12: Credit-wallet spend on analyses and packs (SME) · connection fee (supplier) · subscription (investor) | C12: =Pricing_Income!F9 -> 2677160 | D12: 5-yr income (RM)
A13: Key resources | B13: Rules engine and bill reader, verified bill dataset, partner network; reused Orbyte Connect, credit wallet, eClaim, eSign and audit log | C13: =Volumes!E10 -> 149760 | D13: Bills analysed (5-yr)
A14: Key activities | B14: Bill extraction and validation, savings calculation, listing and matching, partner onboarding | C14: =Volumes!H10 -> 4160 | D14: Packs generated (5-yr)
A15: Key partners | B15: Alpha Red / Orbyte (platform and distribution); licensed banks and DFIs; SEDA-registered PV providers and equipment dealers; Energy Commission data (tariff, grid factor) | C15: =Assumptions!F23 -> 18 | D15: Paying investors (Y5)
A16: Cost structure | B16: People (lean team on Orbyte's platform), acquisition, compliance (PDPA), hosting, AI reading and payment processing | C16: =Spendings!K9 -> 1603235.2 | D16: 5-yr spend (RM)
A19: Revenue mix (5-year)
A20: Stream | B20: Who pays · when | C20: 5-yr income (RM) | D20: Share of income
A21: Bill analyses | B21: SME · per bill, from the credit wallet after the free credit | C21: =Pricing_Income!B9 -> 199520 | D21: =IF(Pricing_Income!$F$9>0,C21/Pricing_Income!$F$9,0) -> 0.074526737
A22: Preparation Pack + partner access | B22: SME · per pack, from the credit wallet | C22: =Pricing_Income!C9 -> 328640 | D22: =IF(Pricing_Income!$F$9>0,C22/Pricing_Income!$F$9,0) -> 0.12275695
A23: Supplier connection fee | B23: Supplier · only when the owner accepts | C23: =Pricing_Income!D9 -> 649000 | D23: =IF(Pricing_Income!$F$9>0,C23/Pricing_Income!$F$9,0) -> 0.24242107
A24: Investor subscription | B24: Bank / investor · monthly | C24: =Pricing_Income!E9 -> 1500000 | D24: =IF(Pricing_Income!$F$9>0,C24/Pricing_Income!$F$9,0) -> 0.56029524
A25: Total | C25: =SUM(C21:C24) -> 2677160 | D25: =SUM(D21:D24) -> 1
A27: Unit economics
A28: Measure | B28: How it is calculated | C28: Year 5 value | D28: Unit
A29: Customer revenue per active customer | B29: (analyses + packs + supplier fees) ÷ active customers, Y5 | C29: =(Pricing_Income!B8+Pricing_Income!C8+Pricing_Income!D8)/Volumes!B9 -> 57.4 | D29: RM/customer/year
A30: Customer acquisition cost | B30: Assumption (in-app promotion via Orbyte) | C30: =Assumptions!$B$85 -> 20 | D30: RM/new customer
A31: CAC payback | B31: CAC ÷ monthly revenue per customer | C31: =IF(C29>0,Assumptions!$B$85/(C29/12),0) -> 4.1811847 | D31: months
A32: Customer ROI (Y5) | B32: (benefits − customer fees) ÷ customer fees, Y5 | C32: =ROI!I9 -> 2.2032138 | D32: %
A33: Run cost per active customer | B33: (AI reading + messaging + hosting) ÷ active customers, Y5 | C33: =(Spendings!B8+Spendings!C8+Spendings!D8)/Volumes!B9 -> 2.6597575 | D33: RM/customer/year
A34: Margin per paid analysis | B34: price − AI reading cost per bill | C34: =Assumptions!$B$91-Assumptions!$B$72*Assumptions!$B$71/3600*Assumptions!$B$70 -> 1.9843466 | D34: RM/analysis
A35: Investor subscription vs benchmark | B35: RM30k/yr vs acquiring fintech customers (CAC > USD1,450 each) | C35: =Assumptions!$B$102*12/(1450*Assumptions!$B$70) -> 5.0666475 | D35: Customers' worth

Sheet Marketing_Plan
A1: Marketing / Go-to-Market Plan — phases, channels, budget and KPIs
A2: Targets and budget link to Volumes and Spendings. Channel descriptions are the plan; budgets are model outputs.
A4: Phase | B4: Y1 Pilot | C4: Y2 Launch | D4: Y3 Scale | E4: Y4 Expand | F4: Y5 Expand | G4: Notes
A5: Objective | B5: Prove the journey with pilot customers in Klang Valley | C5: In-app launch to existing Orbyte users | D5: Scale in manufacturing and F&B | E5: Extend to other states | F5: Add new upgrade types
A6: Active Customers | B6: =Volumes!B5 -> 300 | C6: =Volumes!B6 -> 1500 | D6: =Volumes!B7 -> 3000 | E6: =Volumes!B8 -> 6000 | F6: =Volumes!B9 -> 10000 | G6: From Volumes
A7: New Customers acquired | B7: =Volumes!C5 -> 300 | C7: =Volumes!C6 -> 1200 | D7: =Volumes!C7 -> 1500 | E7: =Volumes!C8 -> 3000 | F7: =Volumes!C9 -> 4000 | G7: From Volumes
A8: Paying investors | B8: =Assumptions!B23 -> 2 | C8: =Assumptions!C23 -> 6 | D8: =Assumptions!D23 -> 10 | E8: =Assumptions!E23 -> 14 | F8: =Assumptions!F23 -> 18 | G8: From Assumptions
A9: Preparation Packs | B9: =Volumes!H5 -> 60 | C9: =Volumes!H6 -> 300 | D9: =Volumes!H7 -> 600 | E9: =Volumes!H8 -> 1200 | F9: =Volumes!H9 -> 2000 | G9: From Volumes
A10: Accepted supplier connections | B10: =Volumes!M5 -> 47 | C10: =Volumes!M6 -> 234 | D10: =Volumes!M7 -> 468 | E10: =Volumes!M8 -> 936 | F10: =Volumes!M9 -> 1560 | G10: From Volumes
A11: Main channels | B11: Orbyte pilot group, 2 founding banks, 5–10 SEDA-registered suppliers | C11: Orbyte in-app launch + eClaim trigger + WhatsApp onboarding | D11: Bank SME units, supplier associations, SME events | E11: Regional supplier partners | F11: Industry associations
A13: Marketing budget (RM)
A14: Item | B14: Y1 | C14: Y2 | D14: Y3 | E14: Y4 | F14: Y5 | G14: Formula
A15: Customer acquisition | B15: =Spendings!F4 -> 6000 | C15: =Spendings!F5 -> 24000 | D15: =Spendings!F6 -> 30000 | E15: =Spendings!F7 -> 60000 | F15: =Spendings!F8 -> 80000 | G15: New Customers × CAC
A16: Partnerships & events | B16: =Spendings!H4 -> 10000 | C16: =Spendings!H5 -> 10000 | D16: =Spendings!H6 -> 10000 | E16: =Spendings!H7 -> 10000 | F16: =Spendings!H8 -> 10000 | G16: Fixed per year
A17: Total marketing | B17: =SUM(B15:B16) -> 16000 | C17: =SUM(C15:C16) -> 34000 | D17: =SUM(D15:D16) -> 40000 | E17: =SUM(E15:E16) -> 70000 | F17: =SUM(F15:F16) -> 90000
A18: Marketing as % of income | B18: =IF(Pricing_Income!F4>0,B17/Pricing_Income!F4,0) -> 0.21203287 | C18: =IF(Pricing_Income!F5>0,C17/Pricing_Income!F5,0) -> 0.13071895 | D18: =IF(Pricing_Income!F6>0,D17/Pricing_Income!F6,0) -> 0.085251492 | E18: =IF(Pricing_Income!F7>0,E17/Pricing_Income!F7,0) -> 0.092299578 | F18: =IF(Pricing_Income!F8>0,F17/Pricing_Income!F8,0) -> 0.080789946
A19: Marketing cost per new customer | B19: =IF(B7>0,B17/B7,0) -> 53.333333 | C19: =IF(C7>0,C17/C7,0) -> 28.333333 | D19: =IF(D7>0,D17/D7,0) -> 26.666667 | E19: =IF(E7>0,E17/E7,0) -> 23.333333 | F19: =IF(F7>0,F17/F7,0) -> 22.5
A21: KPI targets
A22: KPI | B22: Target | G22: Why it matters
A23: Pack rate | B23: =Assumptions!$B$19 -> 0.2 | G23: Customers moving from bill checks to upgrade planning and partner access
A24: Listing rate (of packs) | B24: =Assumptions!$B$20 -> 0.52 | G24: Customers willing to be found by investors and suppliers
A25: Upgrade completion (of listings / yr) | B25: =Assumptions!$B$21 -> 0.26 | G25: Real-world impact and supplier value
A26: Accepted connections per listing | B26: =Assumptions!$B$22 -> 1.5 | G26: Supplier lead quality
A27: Bill-check time (minutes) | B27: =Assumptions!$B$31 -> 3 | G27: Productivity claim — prove in user test
A28: Monthly active rate | B28: =Assumptions!$B$18 -> 0.6 | G28: Share of monthly bills analysed (eClaim trigger or forwarded bill)
A30: Channel plan
A31: Channel | B31: Audience | C31: Tactic | G31: Success measure
A32: Orbyte in-app | B32: Existing Orbyte customers | C32: In-app prompt in Orbyte and eClaim; RM10 free starting credit in the wallet | G32: New Customers per month
A33: WhatsApp | B33: SME owners and staff | C33: Forward bill → instant summary; referral link | G33: Bills per active customer
A34: Bank SME units | B34: Banks and DFIs | C34: Pilot subscription with 2 founding partners; deal-flow demo | G34: Paying investors
A35: Supplier associations | B35: SEDA-registered PV providers, aircon and lighting dealers | C35: Free listing preview; pay per accepted connection | G35: Accepted connections
A36: SME events and webinars | B36: Manufacturing and F&B owners | C36: Live bill-check demo; case study from pilot | G36: Sign-ups per event

Sheet References
A1: References
A3: Ref | B3: What it supports | C3: Link
A4: [1] | B4: SME Corp Malaysia (DOSM data) — Profile of MSMEs 2023: 767,421 micro, 314,465 small; 59,316 MSMEs in manufacturing | C4: https://smecorp.gov.my/index.php/en/policies/2020-02-11-08-01-24/profile-and-importance-to-the-economy
A5: [2] | B5: DOSM — Economic Census 2023, Food & Beverage Services: 136,453 establishments | C5: https://www.dosm.gov.my/portal-main/release-content/economic-census-2023-food-and-beverage-services-sector
A6: [3] | B6: Plus Xnergy — July 2025 TNB tariff: Low Voltage General energy RM0.2703, capacity RM0.0883, network RM0.1482 per kWh | C6: https://www.plusxnergy.com/?p=2574
A7: [4] | B7: Energy Commission — Grid Emission Factor in Malaysia 2022–2024 (Provisional): Peninsular 2024 = 0.740 kg CO2e/kWh | C7: https://myenergystats.st.gov.my/documents/d/guest/grid-emission-factor-gef-in-malaysia-2022-2024-provisional-
A8: [5] | B8: Salleh et al. (2018), IEEE SCOReD, UNITEN — inverter air conditioners use 33% less electricity on average | C8: https://irepository.uniten.edu.my/entities/publication/c8d304dd-1a3c-45c0-84d5-eecaeeaf3549/full
A9: [6] | B9: Green Energy and Fuel Research (Jun 2026) — LED retrofit in a Malaysian university building cut energy 44.7% (70,810 kWh/yr) | C9: https://www.sciltp.com/journals/gefr/articles/2603003371
A10: [7] | B10: Lapasar (Malaysia) — Philips Ecofit LED T8 4ft 18W tube: RM11.11 | C10: https://mall.lapasar.com/products/201519
A11: [8] | B11: Recommend.my — electrical service prices (KL/Selangor): fluorescent light fixture RM30 per unit | C11: https://recommend.my/blog/?p=19104
A12: [9] | B12: LG Malaysia — 1.5HP non-inverter air conditioner BS-C126HYA0: cooling power input 1,020 W | C12: https://www.lg.com/my/residential-air-conditioners/single-split-air-conditioners/bs-c126hya0/
A13: [10] | B13: Haier Malaysia (Mar 2026) — 1.5HP inverter air conditioner price RM1,200–2,500 | C13: https://www.haier.com/my/about-haier/articles/20260326_288449.shtml
A14: [11] | B14: Recommend.my — air-conditioner installation: 1.5HP wall unit RM350 | C14: https://www.recommend.my/service/air-conditioning
... A47: [44] | B47: Orbyte (Alpha Red Pro Sdn Bhd) — SME business operating system: Connect (one sign-in, roles, approval workflows), eClaim and eSign charged per use, one credit wallet across every module, free to start, no per-seat fees | C47: https://orbyte.my
A49: All sources accessed 22–24 Oct 2026. 'Team' in the Assumptions sheet marks team estimates to be validated by the user test and partner interviews.
